<?xml version="1.0"?>
<robot xmlns:xacro="http://www.ros.org/wiki/xacro" name="simple_rover">

  <!-- ==================== Parameters ==================== -->
  <xacro:property name="body_length" value="0.4"/>
  <xacro:property name="body_width"  value="0.3"/>
  <xacro:property name="body_height" value="0.1"/>
  <xacro:property name="body_mass"   value="5.0"/>

  <xacro:property name="wheel_radius" value="0.06"/>
  <xacro:property name="wheel_width"  value="0.04"/>
  <xacro:property name="wheel_mass"   value="0.5"/>

  <!-- Wheel placement offsets from base_link center -->
  <xacro:property name="wheel_x_front" value="0.13"/>
  <xacro:property name="wheel_x_rear"  value="-0.13"/>
  <xacro:property name="wheel_y"       value="${(body_width / 2) + (wheel_width / 2) + 0.01}"/>
  <xacro:property name="wheel_z"       value="-0.02"/>

  <!-- ==================== Materials ==================== -->
  <material name="blue">
    <color rgba="0.2 0.4 0.8 1.0"/>
  </material>
  <material name="dark_grey">
    <color rgba="0.3 0.3 0.3 1.0"/>
  </material>

  <!-- ==================== Inertia Macros ==================== -->
  <xacro:macro name="box_inertia" params="m x y z">
    <inertial>
      <mass value="${m}"/>
      <inertia ixx="${m*(y*y+z*z)/12}" ixy="0" ixz="0"
               iyy="${m*(x*x+z*z)/12}" iyz="0"
               izz="${m*(x*x+y*y)/12}"/>
    </inertial>
  </xacro:macro>

  <xacro:macro name="cylinder_inertia" params="m r h">
    <inertial>
      <mass value="${m}"/>
      <inertia ixx="${m*(3*r*r+h*h)/12}" ixy="0" ixz="0"
               iyy="${m*(3*r*r+h*h)/12}" iyz="0"
               izz="${m*r*r/2}"/>
    </inertial>
  </xacro:macro>

  <!-- ==================== Wheel Macro ==================== -->
  <xacro:macro name="wheel" params="prefix x_offset y_sign">
    <link name="${prefix}_wheel_link">
      <visual>
        <geometry>
          <cylinder radius="${wheel_radius}" length="${wheel_width}"/>
        </geometry>
        <material name="dark_grey"/>
      </visual>
      <collision>
        <geometry>
          <cylinder radius="${wheel_radius}" length="${wheel_width}"/>
        </geometry>
      </collision>
      <xacro:cylinder_inertia m="${wheel_mass}" r="${wheel_radius}" h="${wheel_width}"/>
    </link>

    <joint name="${prefix}_wheel_joint" type="continuous">
      <parent link="base_link"/>
      <child link="${prefix}_wheel_link"/>
      <origin xyz="${x_offset} ${y_sign * wheel_y} ${wheel_z}" rpy="${-pi/2} 0 0"/>
      <axis xyz="0 0 1"/>
      <dynamics friction="1.0" damping="0.1"/>
    </joint>
  </xacro:macro>

  <!-- ==================== Base Link ==================== -->
  <link name="base_link">
    <visual>
      <geometry>
        <box size="${body_length} ${body_width} ${body_height}"/>
      </geometry>
      <material name="blue"/>
    </visual>
    <collision>
      <geometry>
        <box size="${body_length} ${body_width} ${body_height}"/>
      </geometry>
    </collision>
    <xacro:box_inertia m="${body_mass}" x="${body_length}" y="${body_width}" z="${body_height}"/>
  </link>

  <!-- base_footprint (on the ground) -->
  <link name="base_footprint"/>
  <joint name="base_footprint_joint" type="fixed">
    <parent link="base_footprint"/>
    <child link="base_link"/>
    <origin xyz="0 0 ${wheel_radius - wheel_z}" rpy="0 0 0"/>
  </joint>

  <!-- ==================== Wheels ==================== -->
  <xacro:wheel prefix="front_left"  x_offset="${wheel_x_front}" y_sign="1"/>
  <xacro:wheel prefix="front_right" x_offset="${wheel_x_front}" y_sign="-1"/>
  <xacro:wheel prefix="rear_left"   x_offset="${wheel_x_rear}"  y_sign="1"/>
  <xacro:wheel prefix="rear_right"  x_offset="${wheel_x_rear}"  y_sign="-1"/>

  <!-- ==================== Gazebo ==================== -->
  <gazebo>
    <plugin filename="gz-sim-diff-drive-system"
            name="gz::sim::systems::DiffDrive">
      <left_joint>front_left_wheel_joint</left_joint>
      <left_joint>rear_left_wheel_joint</left_joint>
      <right_joint>front_right_wheel_joint</right_joint>
      <right_joint>rear_right_wheel_joint</right_joint>
      <wheel_separation>${2 * wheel_y}</wheel_separation>
      <wheel_radius>${wheel_radius}</wheel_radius>
      <max_linear_acceleration>1.0</max_linear_acceleration>
      <min_linear_acceleration>-1.0</min_linear_acceleration>
      <max_angular_acceleration>2.0</max_angular_acceleration>
      <min_angular_acceleration>-2.0</min_angular_acceleration>
      <topic>cmd_vel</topic>
      <odom_topic>odom</odom_topic>
      <tf_topic>tf</tf_topic>
      <frame_id>odom</frame_id>
      <child_frame_id>base_footprint</child_frame_id>
      <odom_publish_frequency>30</odom_publish_frequency>
    </plugin>

    <plugin filename="gz-sim-joint-state-publisher-system"
            name="gz::sim::systems::JointStatePublisher">
      <topic>joint_states</topic>
    </plugin>
  </gazebo>

  <!-- Wheel friction -->
  <gazebo reference="front_left_wheel_link">
    <mu1>1.0</mu1>
    <mu2>0.5</mu2>
  </gazebo>
  <gazebo reference="front_right_wheel_link">
    <mu1>1.0</mu1>
    <mu2>0.5</mu2>
  </gazebo>
  <gazebo reference="rear_left_wheel_link">
    <mu1>1.0</mu1>
    <mu2>0.5</mu2>
  </gazebo>
  <gazebo reference="rear_right_wheel_link">
    <mu1>1.0</mu1>
    <mu2>0.5</mu2>
  </gazebo>

</robot>
